<mujoco model="GEN3-6DOF_NO-VISION_URDF_ARM_V01">
    <compiler angle="radian" meshdir="/home/yons/cassie-stuff/arm-cassie/cassie_gen3_description/meshes/" />
    <size njmax="500" nconmax="100" />
    <asset>
        <mesh name="pelvis" file="pelvis.stl" />
        <mesh name="base_link" file="base_link.stl" />
        <mesh name="shoulder_link" file="shoulder_link.stl" />
        <mesh name="bicep_link" file="bicep_link.stl" />
        <mesh name="forearm_link" file="forearm_link.stl" />
        <mesh name="spherical_wrist_1_link" file="spherical_wrist_1_link.stl" />
        <mesh name="spherical_wrist_2_link" file="spherical_wrist_2_link.stl" />
        <mesh name="bracelet_no_vision_link" file="bracelet_no_vision_link.stl" />
    </asset>
    <worldbody>
        <geom type="mesh" contype="0" conaffinity="0" group="1" rgba="0.2 0.2 0.2 1" mesh="pelvis" />
        <geom size="0.13" rgba="0.2 0.2 0.2 1" />
        <geom pos="0 0 0.1" type="mesh" contype="0" conaffinity="0" group="1" rgba="0.75294 0.75294 0.75294 1" mesh="base_link" />
        <body name="shoulder_link" pos="0 0 0.25643" quat="-3.67321e-06 -1 0 0">
            <inertial pos="-2.3e-05 -0.010364 -0.07336" quat="0.707051 0.0451246 -0.0453544 0.704263" mass="1.377" diaginertia="0.00488868 0.00457 0.00135132" />
            <joint name="joint_1" pos="0 0 0" axis="0 0 1" />
            <geom type="mesh" contype="0" conaffinity="0" group="1" rgba="0.75294 0.75294 0.75294 1" mesh="shoulder_link" />
            <body name="bicep_link" pos="0 0.005375 -0.12838" quat="0.707105 0.707108 0 0">
                <inertial pos="3.5e-05 -0.208207 -0.01889" quat="0.499531 0.50049 -0.500566 0.499411" mass="1.262" diaginertia="0.0471882 0.046752 0.000849791" />
                <joint name="joint_2" pos="0 0 0" axis="0 0 1" limited="true" range="-2.41 2.41" />
                <geom type="mesh" contype="0" conaffinity="0" group="1" rgba="0.75294 0.75294 0.75294 1" mesh="bicep_link" />
                <body name="forearm_link" pos="0 -0.41 0" quat="-3.67321e-06 1 0 0">
                    <inertial pos="1.8e-05 0.076168 -0.01397" quat="0.513497 0.485985 -0.486188 0.513577" mass="0.93" diaginertia="0.00848774 0.008292 0.000604256" />
                    <joint name="joint_3" pos="0 0 0" axis="0 0 1" limited="true" range="-2.66 2.66" />
                    <geom type="mesh" contype="0" conaffinity="0" group="1" rgba="0.75294 0.75294 0.75294 1" mesh="forearm_link" />
                    <body name="spherical_wrist_1_link" pos="0 0.20843 -0.006375" quat="0.707105 0.707108 0 0">
                        <inertial pos="-1e-06 0.008486 -0.062937" quat="0.704382 -0.062019 0.062019 0.704382" mass="0.678" diaginertia="0.00170753 0.001645 0.000347472" />
                        <joint name="joint_4" pos="0 0 0" axis="0 0 1" />
                        <geom type="mesh" contype="0" conaffinity="0" group="1" rgba="0.75294 0.75294 0.75294 1" mesh="spherical_wrist_1_link" />
                        <body name="spherical_wrist_2_link" pos="0 -0.00017505 -0.10593" quat="0.707105 -0.707108 0 0">
                            <inertial pos="-1e-06 0.046429 -0.008704" quat="0.5446 0.451011 -0.451011 0.5446" mass="0.678" diaginertia="0.00174437 0.001685 0.000351632" />
                            <joint name="joint_5" pos="0 0 0" axis="0 0 1" limited="true" range="-2.23 2.23" />
                            <geom type="mesh" contype="0" conaffinity="0" group="1" rgba="0.75294 0.75294 0.75294 1" mesh="spherical_wrist_2_link" />
                            <body name="bracelet_link" pos="0 0.10593 -0.00017505" quat="0.707105 0.707108 0 0">
                                <inertial pos="-9.3e-05 0.000132 -0.022905" quat="-0.0368025 0.719402 -0.0444884 0.69219" mass="0.364" diaginertia="0.00024027 0.000222769 0.000213961" />
                                <joint name="joint_6" pos="0 0 0" axis="0 0 1" />
                                <geom type="mesh" contype="0" conaffinity="0" group="1" rgba="0.75294 0.75294 0.75294 1" mesh="bracelet_no_vision_link" />
                            </body>
                        </body>
                    </body>
                </body>
            </body>
        </body>
    </worldbody>
</mujoco>
