<mujoco model="KR7108-URDF">
    <compiler angle="radian" />
    <size njmax="500" nconmax="100" />
    <asset>
        <mesh name="base_link" file="base_link.STL" />
        <mesh name="shoulder_link" file="shoulder_link.STL" />
        <mesh name="arm_link" file="arm_link.STL" />
        <mesh name="forearm_link" file="forearm_link.STL" />
        <mesh name="lower_wrist_link" file="lower_wrist_link.STL" />
        <mesh name="upper_wrist_link" file="upper_wrist_link.STL" />
    </asset>
    <worldbody>
        <body name="BASE" pos="0 0 0">
            <inertial pos="0.00244324 0.00015573 0.0861674" quat="0.999765 0.000276221 -0.0211882 0.00451385" mass="1.14608" diaginertia="0.0033632 0.003311 0.000766919" />
            <joint name="END_EFFECTOR" pos="0 0 0" axis="0 0 1" />
            <geom type="mesh" mesh="base_link" />
            <body name="SHOULDER" pos="0 0 0.12825">
                <inertial pos="2.477e-05 0.0221353 0.0993769" quat="0.972429 0.233194 -0.000430944 0.00108761" mass="0.959744" diaginertia="0.00165947 0.00158128 0.000717195" />
                <joint name="J0" pos="0 0 0" axis="0 0 1" limited="true" range="-2.76 2.76" />
                <geom type="mesh" mesh="shoulder_link" />
                <body name="ARM" pos="0 -0.03 0.115" quat="0.707105 0.707108 0 0">
                    <inertial pos="0.029983 0.211548 0.0453031" quat="0.534676 0.467794 -0.46336 0.529706" mass="1.17756" diaginertia="0.0115237 0.0114928 0.000839712" />
                    <joint name="J1" pos="0 0 0" axis="0 0 1" limited="true" range="-2.76 2.76" />
                    <geom type="mesh" mesh="arm_link" />
                    <body name="FOREARM" pos="0 0.28 0" quat="-3.67321e-06 -1 0 0">
                        <inertial pos="0.0301559 0.0950221 0.0073555" quat="0.523543 0.49139 -0.473675 0.50997" mass="0.597677" diaginertia="0.00169754 0.00163253 0.000291376" />
                        <joint name="J2" pos="0 0 0" axis="0 0 1" limited="true" range="-2.76 2.76" />
                        <geom type="mesh" mesh="forearm_link" />
                        <body name="LOWER_WRIST" pos="0 -0.14 0.02" quat="0.707105 0.707108 0 0">
                            <inertial pos="0.00575149 0.0100044 0.0871921" quat="0.700403 -0.13124 -0.134345 0.688595" mass="0.526934" diaginertia="0.000785199 0.000756398 0.000275722" />
                            <joint name="J3" pos="0 0 0" axis="0 0 1" limited="true" range="-2.67 2.67" />
                            <geom type="mesh" mesh="lower_wrist_link" />
                            <body name="UPPER_WRIST" pos="0.0285 0 0.105" quat="0.707105 0 0.707108 0">
                                <inertial pos="0.0805652 0.00980409 0.018728" quat="0.00431726 0.708285 -4.18922e-06 0.705913" mass="0.580973" diaginertia="0.00108466 0.00106374 0.000212638" />
                                <joint name="J4" pos="0 0 0" axis="0 0 1" limited="true" range="-2.67 2.67" />
                                <geom type="mesh" mesh="upper_wrist_link" />
                                <body name="END_EFFECTOR" pos="-0.105 0 0.0285" quat="0.707105 0 -0.707108 0">
                                    <inertial pos="0 0 0" quat="0.999765 0.000276221 -0.0211882 0.00451385" mass="0.1" diaginertia="3.3632e-05 3.311e-05 7.66919e-06" />
                                    <joint name="J5" pos="0 0 0" axis="0 0 1" limited="true" range="-2.67 2.67" />
                                </body>
                            </body>
                        </body>
                    </body>
                </body>
            </body>
        </body>
    </worldbody>
</mujoco>
